Workbook

Sheet Inventário
A1: Origem | B1: Item | C1: Qtd. | D1: Valor real (gp) | E1: Valor estimado (gp) | F1: Como foi estimado | G1: Categoria | H1: Vender? | I1: Valor base (gp) | J1: Bônus aplicado | K1: Venda líquida (gp) | L1: Observação
A2: Goblin — primeira sala | B2: Cimitarra | C2: 1 | E2: 25 | F2: Preço de lista D&D 5e | G2: Item comum | H2: Sim | I2: =IF(D2<>"",D2,IF(E2<>"",E2,0)) -> 25 | J2: =IF(G2="Joia",Parametros!$B$3,IF(G2="Mágico",Parametros!$B$4,Parametros!$B$2)) -> 0.15 | K2: =IF(H2="Sim",I2*(1+J2),0) -> 28.75
A3: Goblin — primeira sala | B3: Escudo | C3: 1 | E3: 10 | F3: Preço de lista D&D 5e | G3: Item comum | H3: Sim | I3: =IF(D3<>"",D3,IF(E3<>"",E3,0)) -> 10 | J3: =IF(G3="Joia",Parametros!$B$3,IF(G3="Mágico",Parametros!$B$4,Parametros!$B$2)) -> 0.15 | K3: =IF(H3="Sim",I3*(1+J3),0) -> 11.5
A4: Humanos — sala escondida 2 | B4: Moedas: 43 pp | C4: 1 | D4: 4.3 | F4: 43 pp × 0,1 gp | G4: Moedas | H4: Não | I4: =IF(D4<>"",D4,IF(E4<>"",E4,0)) -> 4.3 | J4: =IF(G4="Joia",Parametros!$B$3,IF(G4="Mágico",Parametros!$B$4,Parametros!$B$2)) -> 0.15 | K4: =IF(H4="Sim",I4*(1+J4),0) -> 0
A5: Humanos — sala escondida 2 | B5: Moedas: 9 gp | C5: 1 | D5: 9 | F5: Valor anotado | G5: Moedas | H5: Não | I5: =IF(D5<>"",D5,IF(E5<>"",E5,0)) -> 9 | J5: =IF(G5="Joia",Parametros!$B$3,IF(G5="Mágico",Parametros!$B$4,Parametros!$B$2)) -> 0.15 | K5: =IF(H5="Sim",I5*(1+J5),0) -> 0
A6: Humanos — sala escondida 2 | B6: 3 Dardos elementais de uso único | C6: 1 | E6: 150 | F6: Estimativa conservadora: 50 gp cada por efeito mágico de uso único | G6: Mágico | H6: Não | I6: =IF(D6<>"",D6,IF(E6<>"",E6,0)) -> 150 | J6: =IF(G6="Joia",Parametros!$B$3,IF(G6="Mágico",Parametros!$B$4,Parametros!$B$2)) -> 0.15 | K6: =IF(H6="Sim",I6*(1+J6),0) -> 0 | L6: Manter com o grupo / confirmar antes de vender.
A7: Dragão | B7: Escama de wyrmling gelada | C7: 1 | E7: 25 | F7: Componente/curiosidade; estimativa conservadora | G7: Especial | H7: Não | I7: =IF(D7<>"",D7,IF(E7<>"",E7,0)) -> 25 | J7: =IF(G7="Joia",Parametros!$B$3,IF(G7="Mágico",Parametros!$B$4,Parametros!$B$2)) -> 0.15 | K7: =IF(H7="Sim",I7*(1+J7),0) -> 0 | L7: Manter com o grupo / confirmar antes de vender.
A8: Kobolds | B8: Concha gigante | C8: 1 | E8: 5 | F8: Curiosidade decorativa; estimativa | G8: Item comum | H8: Não | I8: =IF(D8<>"",D8,IF(E8<>"",E8,0)) -> 5 | J8: =IF(G8="Joia",Parametros!$B$3,IF(G8="Mágico",Parametros!$B$4,Parametros!$B$2)) -> 0.15 | K8: =IF(H8="Sim",I8*(1+J8),0) -> 0
A9: Kobolds | B9: Material para criar crossbow | C9: 1 | E9: 12.5 | F9: Metade do preço de uma light crossbow (25 gp) | G9: Item comum | H9: Não | I9: =IF(D9<>"",D9,IF(E9<>"",E9,0)) -> 12.5 | J9: =IF(G9="Joia",Parametros!$B$3,IF(G9="Mágico",Parametros!$B$4,Parametros!$B$2)) -> 0.15 | K9: =IF(H9="Sim",I9*(1+J9),0) -> 0
A10: Kobolds | B10: Ferro útil (4 kg / 8 lb) | C10: 1 | E10: 0.8 | F10: Ferro bruto estimado: 0,1 gp/lb | G10: Item comum | H10: Sim | I10: =IF(D10<>"",D10,IF(E10<>"",E10,0)) -> 0.8 | J10: =IF(G10="Joia",Parametros!$B$3,IF(G10="Mágico",Parametros!$B$4,Parametros!$B$2)) -> 0.15 | K10: =IF(H10="Sim",I10*(1+J10),0) -> 0.92
A11: Esqueletos | B11: Apito Nightcaller | C11: 1 | E11: 500 | F11: Item mágico raro; valor de referência muito incerto | G11: Mágico | H11: Não | I11: =IF(D11<>"",D11,IF(E11<>"",E11,0)) -> 500 | J11: =IF(G11="Joia",Parametros!$B$3,IF(G11="Mágico",Parametros!$B$4,Parametros!$B$2)) -> 0.15 | K11: =IF(H11="Sim",I11*(1+J11),0) -> 0 | L11: Manter com o grupo / confirmar antes de vender.
A12: Esqueletos | B12: Poção de resistência a fogo | C12: 1 | E12: 300 | F12: Poção mágica incomum; estimativa | G12: Mágico | H12: Não | I12: =IF(D12<>"",D12,IF(E12<>"",E12,0)) -> 300 | J12: =IF(G12="Joia",Parametros!$B$3,IF(G12="Mágico",Parametros!$B$4,Parametros!$B$2)) -> 0.15 | K12: =IF(H12="Sim",I12*(1+J12),0) -> 0 | L12: Manter com o grupo / confirmar antes de vender.
A13: Esqueletos | B13: Poção de sopro de fogo | C13: 1 | E13: 150 | F13: Poção mágica incomum; estimativa | G13: Mágico | H13: Não | I13: =IF(D13<>"",D13,IF(E13<>"",E13,0)) -> 150 | J13: =IF(G13="Joia",Parametros!$B$3,IF(G13="Mágico",Parametros!$B$4,Parametros!$B$2)) -> 0.15 | K13: =IF(H13="Sim",I13*(1+J13),0) -> 0 | L13: Manter com o grupo / confirmar antes de vender.
A14: Esqueletos | B14: Vela | C14: 1 | E14: 0.01 | F14: Preço de lista D&D 5e | G14: Item comum | H14: Sim | I14: =IF(D14<>"",D14,IF(E14<>"",E14,0)) -> 0.01 | J14: =IF(G14="Joia",Parametros!$B$3,IF(G14="Mágico",Parametros!$B$4,Parametros!$B$2)) -> 0.15 | K14: =IF(H14="Sim",I14*(1+J14),0) -> 0.0115
A15: Esqueletos | B15: 9 pequenas estátuas de dragão em jade | C15: 1 | E15: 90 | F15: Estimativa: 10 gp cada; confirmar avaliação | G15: Joia | H15: Sim | I15: =IF(D15<>"",D15,IF(E15<>"",E15,0)) -> 90 | J15: =IF(G15="Joia",Parametros!$B$3,IF(G15="Mágico",Parametros!$B$4,Parametros!$B$2)) -> 0.05 | K15: =IF(H15="Sim",I15*(1+J15),0) -> 94.5
A16: Ratão | B16: Moedas: 312 pp | C16: 1 | D16: 31.2 | F16: 312 pp × 0,1 gp | G16: Moedas | H16: Não | I16: =IF(D16<>"",D16,IF(E16<>"",E16,0)) -> 31.2 | J16: =IF(G16="Joia",Parametros!$B$3,IF(G16="Mágico",Parametros!$B$4,Parametros!$B$2)) -> 0.15 | K16: =IF(H16="Sim",I16*(1+J16),0) -> 0
A17: Ratão | B17: Moedas: 68 gp | C17: 1 | D17: 68 | F17: Valor anotado | G17: Moedas | H17: Não | I17: =IF(D17<>"",D17,IF(E17<>"",E17,0)) -> 68 | J17: =IF(G17="Joia",Parametros!$B$3,IF(G17="Mágico",Parametros!$B$4,Parametros!$B$2)) -> 0.15 | K17: =IF(H17="Sim",I17*(1+J17),0) -> 0
A18: Ratão | B18: Pepita de ouro | C18: 1 | D18: 17 | F18: Valor anotado | G18: Moedas | H18: Não | I18: =IF(D18<>"",D18,IF(E18<>"",E18,0)) -> 17 | J18: =IF(G18="Joia",Parametros!$B$3,IF(G18="Mágico",Parametros!$B$4,Parametros!$B$2)) -> 0.15 | K18: =IF(H18="Sim",I18*(1+J18),0) -> 0
A19: Ratão | B19: Anel dourado de Karakas | C19: 1 | E19: 25 | F19: Joia simples; mas pertence ao ranger Karakas | G19: Item de missão | H19: Não | I19: =IF(D19<>"",D19,IF(E19<>"",E19,0)) -> 25 | J19: =IF(G19="Joia",Parametros!$B$3,IF(G19="Mágico",Parametros!$B$4,Parametros!$B$2)) -> 0.15 | K19: =IF(H19="Sim",I19*(1+J19),0) -> 0 | L19: Manter com o grupo / confirmar antes de vender.
A20: Ratão | B20: 2 Adagas | C20: 1 | E20: 4 | F20: 2 × 2 gp (preço de lista) | G20: Item comum | H20: Sim | I20: =IF(D20<>"",D20,IF(E20<>"",E20,0)) -> 4 | J20: =IF(G20="Joia",Parametros!$B$3,IF(G20="Mágico",Parametros!$B$4,Parametros!$B$2)) -> 0.15 | K20: =IF(H20="Sim",I20*(1+J20),0) -> 4.6
A21: Ratão | B21: Arco longo | C21: 1 | E21: 50 | F21: Preço de lista D&D 5e | G21: Item comum | H21: Sim | I21: =IF(D21<>"",D21,IF(E21<>"",E21,0)) -> 50 | J21: =IF(G21="Joia",Parametros!$B$3,IF(G21="Mágico",Parametros!$B$4,Parametros!$B$2)) -> 0.15 | K21: =IF(H21="Sim",I21*(1+J21),0) -> 57.5
A22: Ratão | B22: Aljava | C22: 1 | E22: 1 | F22: Preço de lista D&D 5e | G22: Item comum | H22: Sim | I22: =IF(D22<>"",D22,IF(E22<>"",E22,0)) -> 1 | J22: =IF(G22="Joia",Parametros!$B$3,IF(G22="Mágico",Parametros!$B$4,Parametros!$B$2)) -> 0.15 | K22: =IF(H22="Sim",I22*(1+J22),0) -> 1.15
A23: Ratão | B23: 3 gemas | C23: 1 | D23: 75 | F23: 3 × 25 gp anotados | G23: Joia | H23: Sim | I23: =IF(D23<>"",D23,IF(E23<>"",E23,0)) -> 75 | J23: =IF(G23="Joia",Parametros!$B$3,IF(G23="Mágico",Parametros!$B$4,Parametros!$B$2)) -> 0.05 | K23: =IF(H23="Sim",I23*(1+J23),0) -> 78.75
A24: Ratão | B24: Waterskin, comida, bedroll, fósforos e 3 tochas | C24: 1 | E24: 4 | F24: Estimativa por equipamento básico; confirmar conteúdo | G24: Item comum | H24: Não | I24: =IF(D24<>"",D24,IF(E24<>"",E24,0)) -> 4 | J24: =IF(G24="Joia",Parametros!$B$3,IF(G24="Mágico",Parametros!$B$4,Parametros!$B$2)) -> 0.15 | K24: =IF(H24="Sim",I24*(1+J24),0) -> 0
A25: Ratão | B25: Concha pequena | C25: 1 | E25: 0.5 | F25: Curiosidade decorativa; estimativa | G25: Item comum | H25: Não | I25: =IF(D25<>"",D25,IF(E25<>"",E25,0)) -> 0.5 | J25: =IF(G25="Joia",Parametros!$B$3,IF(G25="Mágico",Parametros!$B$4,Parametros!$B$2)) -> 0.15 | K25: =IF(H25="Sim",I25*(1+J25),0) -> 0
A26: Goblins mortos / goblin cativo | B26: Moedas: 50 gp | C26: 1 | D26: 50 | F26: Valor anotado | G26: Moedas | H26: Não | I26: =IF(D26<>"",D26,IF(E26<>"",E26,0)) -> 50 | J26: =IF(G26="Joia",Parametros!$B$3,IF(G26="Mágico",Parametros!$B$4,Parametros!$B$2)) -> 0.15 | K26: =IF(H26="Sim",I26*(1+J26),0) -> 0
A27: Goblins mortos / goblin cativo | B27: Cimitarra | C27: 1 | E27: 25 | F27: Preço de lista D&D 5e | G27: Item comum | H27: Sim | I27: =IF(D27<>"",D27,IF(E27<>"",E27,0)) -> 25 | J27: =IF(G27="Joia",Parametros!$B$3,IF(G27="Mágico",Parametros!$B$4,Parametros!$B$2)) -> 0.15 | K27: =IF(H27="Sim",I27*(1+J27),0) -> 28.75
A28: Goblins mortos / goblin cativo | B28: Arco curto | C28: 1 | E28: 25 | F28: Preço de lista D&D 5e | G28: Item comum | H28: Sim | I28: =IF(D28<>"",D28,IF(E28<>"",E28,0)) -> 25 | J28: =IF(G28="Joia",Parametros!$B$3,IF(G28="Mágico",Parametros!$B$4,Parametros!$B$2)) -> 0.15 | K28: =IF(H28="Sim",I28*(1+J28),0) -> 28.75
A29: Goblins mortos / goblin cativo | B29: Chave | C29: 1 | E29: 0 | F29: Chave de dungeon; sem venda até confirmar uso | G29: Item de missão | H29: Sim | I29: =IF(D29<>"",D29,IF(E29<>"",E29,0)) -> 0 | J29: =IF(G29="Joia",Parametros!$B$3,IF(G29="Mágico",Parametros!$B$4,Parametros!$B$2)) -> 0.15 | K29: =IF(H29="Sim",I29*(1+J29),0) -> 0 | L29: Manter com o grupo / confirmar antes de vender.
A30: Goblins mortos / goblin cativo | B30: Frasco prateado de Durgeddin com vinho goblin | C30: 1 | D30: 50 | F30: Valor anotado | G30: Arte | H30: Sim | I30: =IF(D30<>"",D30,IF(E30<>"",E30,0)) -> 50 | J30: =IF(G30="Joia",Parametros!$B$3,IF(G30="Mágico",Parametros!$B$4,Parametros!$B$2)) -> 0.15 | K30: =IF(H30="Sim",I30*(1+J30),0) -> 57.5
A31: Goblins mortos / goblin cativo | B31: 9 arcos curtos | C31: 1 | E31: 225 | F31: 9 × 25 gp (preço de lista) | G31: Item comum | H31: Sim | I31: =IF(D31<>"",D31,IF(E31<>"",E31,0)) -> 225 | J31: =IF(G31="Joia",Parametros!$B$3,IF(G31="Mágico",Parametros!$B$4,Parametros!$B$2)) -> 0.15 | K31: =IF(H31="Sim",I31*(1+J31),0) -> 258.75
A32: Goblins mortos / goblin cativo | B32: 2 cimitarras | C32: 1 | E32: 50 | F32: 2 × 25 gp (preço de lista) | G32: Item comum | H32: Sim | I32: =IF(D32<>"",D32,IF(E32<>"",E32,0)) -> 50 | J32: =IF(G32="Joia",Parametros!$B$3,IF(G32="Mágico",Parametros!$B$4,Parametros!$B$2)) -> 0.15 | K32: =IF(H32="Sim",I32*(1+J32),0) -> 57.5
A33: Sala ao lado dos goblins mortos | B33: 5 frascos de óleo | C33: 1 | E33: 0.5 | F33: 5 × 0,1 gp (preço de lista) | G33: Item comum | H33: Não | I33: =IF(D33<>"",D33,IF(E33<>"",E33,0)) -> 0.5 | J33: =IF(G33="Joia",Parametros!$B$3,IF(G33="Mágico",Parametros!$B$4,Parametros!$B$2)) -> 0.15 | K33: =IF(H33="Sim",I33*(1+J33),0) -> 0
A34: Sala ao lado dos goblins mortos | B34: Caracol vivo | C34: 1 | E34: 1 | F34: Animal/curiosidade; estimativa | G34: Especial | H34: Não | I34: =IF(D34<>"",D34,IF(E34<>"",E34,0)) -> 1 | J34: =IF(G34="Joia",Parametros!$B$3,IF(G34="Mágico",Parametros!$B$4,Parametros!$B$2)) -> 0.15 | K34: =IF(H34="Sim",I34*(1+J34),0) -> 0 | L34: Manter com o grupo / confirmar antes de vender.
A35: Goblins do topo | B35: 2 cimitarras | C35: 1 | E35: 50 | F35: 2 × 25 gp (preço de lista) | G35: Item comum | H35: Sim | I35: =IF(D35<>"",D35,IF(E35<>"",E35,0)) -> 50 | J35: =IF(G35="Joia",Parametros!$B$3,IF(G35="Mágico",Parametros!$B$4,Parametros!$B$2)) -> 0.15 | K35: =IF(H35="Sim",I35*(1+J35),0) -> 57.5
A36: Goblins do topo | B36: 3 arcos curtos | C36: 1 | E36: 75 | F36: 3 × 25 gp (preço de lista) | G36: Item comum | H36: Sim | I36: =IF(D36<>"",D36,IF(E36<>"",E36,0)) -> 75 | J36: =IF(G36="Joia",Parametros!$B$3,IF(G36="Mágico",Parametros!$B$4,Parametros!$B$2)) -> 0.15 | K36: =IF(H36="Sim",I36*(1+J36),0) -> 86.25
A37: Goblins do topo | B37: Concha de caracol bonita | C37: 1 | E37: 1 | F37: Curiosidade decorativa; estimativa | G37: Item comum | H37: Não | I37: =IF(D37<>"",D37,IF(E37<>"",E37,0)) -> 1 | J37: =IF(G37="Joia",Parametros!$B$3,IF(G37="Mágico",Parametros!$B$4,Parametros!$B$2)) -> 0.15 | K37: =IF(H37="Sim",I37*(1+J37),0) -> 0
A38: Caltrix | B38: Estátua de dragão em jade | C38: 1 | D38: 20 | F38: Valor anotado | G38: Joia | H38: Sim | I38: =IF(D38<>"",D38,IF(E38<>"",E38,0)) -> 20 | J38: =IF(G38="Joia",Parametros!$B$3,IF(G38="Mágico",Parametros!$B$4,Parametros!$B$2)) -> 0.05 | K38: =IF(H38="Sim",I38*(1+J38),0) -> 21
A39: Caltrix | B39: Cálice de cristal | C39: 1 | D39: 5 | F39: Valor anotado | G39: Arte | H39: Sim | I39: =IF(D39<>"",D39,IF(E39<>"",E39,0)) -> 5 | J39: =IF(G39="Joia",Parametros!$B$3,IF(G39="Mágico",Parametros!$B$4,Parametros!$B$2)) -> 0.15 | K39: =IF(H39="Sim",I39*(1+J39),0) -> 5.75
A40: Caltrix | B40: 24 peças de prataria | C40: 1 | D40: 24 | F40: 24 × 1 gp anotado | G40: Arte | H40: Sim | I40: =IF(D40<>"",D40,IF(E40<>"",E40,0)) -> 24 | J40: =IF(G40="Joia",Parametros!$B$3,IF(G40="Mágico",Parametros!$B$4,Parametros!$B$2)) -> 0.15 | K40: =IF(H40="Sim",I40*(1+J40),0) -> 27.6
...

Sheet Resumo
A1: Resumo do caixa e divisão — Amigos do Zé Colmeia
A3: Componente | B3: Total (gp)
A4: Moedas e recompensas em caixa | B4: =SUM(Calculos!D2:D104) -> 2604.6
A5: Receita estimada de vendas | B5: =SUM(Calculos!E2:E104) -> 1771.0365
A6: Total disponível para dividir | B6: =B4+B5 -> 4375.6365
A7: Divisão por pessoa | B7: =B6/Parametros!$B$5 -> 1458.5455
A8: Itens mantidos (valor de referência) | B8: =SUM(Calculos!F2:F104) -> 5623
A10: Personagem | B10: Parte igual (gp)
A11: Karstaag | B11: =$B$7 -> 1458.5455
A12: Thorbir | B12: =$B$7 -> 1458.5455
A13: Mercival | B13: =$B$7 -> 1458.5455
A15: Notas
A16: • Itens marcados como “Não” não entram na venda nem na divisão de caixa.
A17: • Moedas e recompensa entram integralmente no caixa; não recebem bônus de venda.
A18: • Bônus aplicados: 15% comuns, 5% joias/arte e 15% mágicos (caso a decisão seja alterada).
A19: • Valores “estimados” são referência de mesa e devem ser ajustados ao avaliar com comerciante/Mestre.

Sheet Parâmetros
A1: Parâmetro | B1: Valor
A2: Bônus de venda — itens comuns | B2: 0.15
A3: Bônus de venda — gemas/arte | B3: 0.05
A4: Bônus de venda — itens mágicos | B4: 0.15
A5: Divisores (membros) | B5: 3

Sheet Parametros
A1: Parâmetro | B1: Valor
A2: Bônus de venda — itens comuns | B2: 0.15
A3: Bônus de venda — gemas/arte | B3: 0.05
A4: Bônus de venda — itens mágicos | B4: 0.15
A5: Divisores (membros) | B5: 3

Sheet Calculos
A1: Categoria | B1: Vender? | C1: Base | D1: Caixa | E1: Venda | F1: Mantido
A2: Item comum | B2: Sim | C2: 25 | D2: 0 | E2: 28.75 | F2: 0
A3: Item comum | B3: Sim | C3: 10 | D3: 0 | E3: 11.5 | F3: 0
A4: Moedas | B4: Não | C4: 4.3 | D4: 4.3 | E4: 0 | F4: 0
A5: Moedas | B5: Não | C5: 9 | D5: 9 | E5: 0 | F5: 0
A6: Mágico | B6: Não | C6: 150 | D6: 0 | E6: 0 | F6: 150
A7: Especial | B7: Não | C7: 25 | D7: 0 | E7: 0 | F7: 25
A8: Item comum | B8: Sim | C8: 5 | D8: 0 | E8: 5.75 | F8: 0
A9: Item comum | B9: Sim | C9: 12.5 | D9: 0 | E9: 14.375 | F9: 0
A10: Item comum | B10: Sim | C10: 0.8 | D10: 0 | E10: 0.92 | F10: 0
A11: Mágico | B11: Não | C11: 500 | D11: 0 | E11: 0 | F11: 500
A12: Mágico | B12: Não | C12: 300 | D12: 0 | E12: 0 | F12: 300
A13: Mágico | B13: Não | C13: 150 | D13: 0 | E13: 0 | F13: 150
... A104: Recompensa | B104: Não | C104: 1500 | D104: 1500 | E104: 0 | F104: 0
